<?xml version="1.0"?>
<robot name="mobile_robot">

    <material name="green">
        <color rgba="0.0 0.8 0.0 1.0"/>
    </material>

    <material name="grey">
        <color rgba="0.8 0.8 0.8 1.0"/>
    </material>
    
    <link name="base_link">
        <visual>
            <geometry>
                <box size="0.5 0.3 0.08"/>
            </geometry>
            <origin xyz="0.0 0.0 0.0" rpy="0.0 0.0 0.0"/>
            <material name="green"/>
        </visual>
    </link>

    <link name="right_wheel_link">
        <visual>
            <geometry>
                <cylinder radius="0.06" length="0.02"/>
            </geometry>
            <origin xyz="0.0 0.0 0.0" rpy="0.0 0.0 0.0"/>
            <material name="grey"/>
        </visual>
    </link>

    <link name="left_wheel_link">
        <visual>
            <geometry>
                <cylinder radius="0.06" length="0.02"/>
            </geometry>
            <origin xyz="0.0 0.0 0.0" rpy="0.0 0.0 0.0"/>
            <material name="grey"/>
        </visual>
    </link>

    <link name="caster_wheel">
        <visual>
            <geometry>
                <sphere radius="0.04"/>
            </geometry>
            <origin xyz="0.0 0.0 0.0" rpy="0.0 0.0 0.0"/>
            <material name="grey"/>
        </visual>
    </link>

    <joint name="base_right_wheel_joint" type="continuous">
        <parent link="base_link"/>
        <child link="right_wheel_link"/>
        <axis xyz="0 0 1"/>
        <origin xyz="0.1 0.16 -0.03" rpy="1.5708 0.0 0.0"/>
    </joint>

    <joint name="base_left_wheel_joint" type="continuous">
        <parent link="base_link"/>
        <child link="left_wheel_link"/>
        <axis xyz="0 0 1"/>
        <origin xyz="0.1 -0.16 -0.03" rpy="1.5708 0.0 0.0"/>
    </joint>

    <joint name="base_caster_wheel_joint" type="fixed">
        <parent link="base_link"/>
        <child link="caster_wheel"/>
        <axis xyz="0 0 1"/>
        <origin xyz="-0.15 0.0 -0.06" rpy="0.0 0.0 0.0"/>
    </joint>

</robot>